[2024-11-25T11:02:12.526+0000] {local_task_job_runner.py:123} INFO - ::group::Pre task execution logs
[2024-11-25T11:02:12.548+0000] {taskinstance.py:2612} INFO - Dependencies all met for dep_context=non-requeueable deps ti=<TaskInstance: get_gbif_data_atropelamento.process_data scheduled__2024-11-25T10:30:00+00:00 [queued]>
[2024-11-25T11:02:12.562+0000] {taskinstance.py:2612} INFO - Dependencies all met for dep_context=requeueable deps ti=<TaskInstance: get_gbif_data_atropelamento.process_data scheduled__2024-11-25T10:30:00+00:00 [queued]>
[2024-11-25T11:02:12.562+0000] {taskinstance.py:2865} INFO - Starting attempt 3 of 4
[2024-11-25T11:02:12.588+0000] {taskinstance.py:2888} INFO - Executing <Task(_PythonDecoratedOperator): process_data> on 2024-11-25 10:30:00+00:00
[2024-11-25T11:02:12.607+0000] {warnings.py:112} WARNING - /home/***/.local/lib/python3.12/site-packages/***/task/task_runner/standard_task_runner.py:70: DeprecationWarning: This process (pid=1257) is multi-threaded, use of fork() may lead to deadlocks in the child.
  pid = os.fork()

[2024-11-25T11:02:12.608+0000] {standard_task_runner.py:72} INFO - Started process 1263 to run task
[2024-11-25T11:02:12.609+0000] {standard_task_runner.py:104} INFO - Running: ['***', 'tasks', 'run', 'get_gbif_data_atropelamento', 'process_data', 'scheduled__2024-11-25T10:30:00+00:00', '--job-id', '1349', '--raw', '--subdir', 'DAGS_FOLDER/gbif_dag.py', '--cfg-path', '/tmp/tmpyqg_teh8']
[2024-11-25T11:02:12.611+0000] {standard_task_runner.py:105} INFO - Job 1349: Subtask process_data
[2024-11-25T11:02:12.675+0000] {task_command.py:467} INFO - Running <TaskInstance: get_gbif_data_atropelamento.process_data scheduled__2024-11-25T10:30:00+00:00 [running]> on host bedd18328759
[2024-11-25T11:02:12.792+0000] {taskinstance.py:3131} INFO - Exporting env vars: AIRFLOW_CTX_DAG_OWNER='***' AIRFLOW_CTX_DAG_ID='get_gbif_data_atropelamento' AIRFLOW_CTX_TASK_ID='process_data' AIRFLOW_CTX_EXECUTION_DATE='2024-11-25T10:30:00+00:00' AIRFLOW_CTX_TRY_NUMBER='3' AIRFLOW_CTX_DAG_RUN_ID='scheduled__2024-11-25T10:30:00+00:00'
[2024-11-25T11:02:12.793+0000] {logging_mixin.py:190} INFO - Task instance is in running state
[2024-11-25T11:02:12.793+0000] {logging_mixin.py:190} INFO -  Previous state of the Task instance: queued
[2024-11-25T11:02:12.794+0000] {logging_mixin.py:190} INFO - Current task name:process_data state:running start_date:2024-11-25 11:02:12.549093+00:00
[2024-11-25T11:02:12.794+0000] {logging_mixin.py:190} INFO - Dag name:get_gbif_data_atropelamento and current dag run status:running
[2024-11-25T11:02:12.794+0000] {taskinstance.py:731} INFO - ::endgroup::
[2024-11-25T11:02:12.795+0000] {taskinstance.py:3310} ERROR - Task failed with exception
Traceback (most recent call last):
  File "/home/airflow/.local/lib/python3.12/site-packages/airflow/models/taskinstance.py", line 767, in _execute_task
    result = _execute_callable(context=context, **execute_callable_kwargs)
             ^^^^^^^^^^^^^^^^^^^^^^^^^^^^^^^^^^^^^^^^^^^^^^^^^^^^^^^^^^^^^
  File "/home/airflow/.local/lib/python3.12/site-packages/airflow/models/taskinstance.py", line 733, in _execute_callable
    return ExecutionCallableRunner(
           ^^^^^^^^^^^^^^^^^^^^^^^^
  File "/home/airflow/.local/lib/python3.12/site-packages/airflow/utils/operator_helpers.py", line 252, in run
    return self.func(*args, **kwargs)
           ^^^^^^^^^^^^^^^^^^^^^^^^^^
  File "/home/airflow/.local/lib/python3.12/site-packages/airflow/models/baseoperator.py", line 406, in wrapper
    return func(self, *args, **kwargs)
           ^^^^^^^^^^^^^^^^^^^^^^^^^^^
  File "/home/airflow/.local/lib/python3.12/site-packages/airflow/decorators/base.py", line 266, in execute
    return_value = super().execute(context)
                   ^^^^^^^^^^^^^^^^^^^^^^^^
  File "/home/airflow/.local/lib/python3.12/site-packages/airflow/models/baseoperator.py", line 406, in wrapper
    return func(self, *args, **kwargs)
           ^^^^^^^^^^^^^^^^^^^^^^^^^^^
  File "/home/airflow/.local/lib/python3.12/site-packages/airflow/operators/python.py", line 238, in execute
    return_value = self.execute_callable()
                   ^^^^^^^^^^^^^^^^^^^^^^^
  File "/home/airflow/.local/lib/python3.12/site-packages/airflow/operators/python.py", line 256, in execute_callable
    return runner.run(*self.op_args, **self.op_kwargs)
           ^^^^^^^^^^^^^^^^^^^^^^^^^^^^^^^^^^^^^^^^^^^
  File "/home/airflow/.local/lib/python3.12/site-packages/airflow/utils/operator_helpers.py", line 252, in run
    return self.func(*args, **kwargs)
           ^^^^^^^^^^^^^^^^^^^^^^^^^^
  File "/opt/airflow/dags/gbif_dag.py", line 262, in process_data
    writer = csv.DictWriter(csvfile, fieldnames=occurrences[0].keys())
                                                ~~~~~~~~~~~^^^
IndexError: list index out of range
[2024-11-25T11:02:12.811+0000] {logging_mixin.py:190} INFO - Task instance in failure state
[2024-11-25T11:02:12.812+0000] {logging_mixin.py:190} INFO - Task start:2024-11-25 11:02:12.549093+00:00 end:2024-11-25 11:02:12.810446+00:00 duration:0.261353
[2024-11-25T11:02:12.812+0000] {logging_mixin.py:190} INFO - Task:<Task(_PythonDecoratedOperator): process_data> dag:<DAG: get_gbif_data_atropelamento> dagrun:<DagRun get_gbif_data_atropelamento @ 2024-11-25 10:30:00+00:00: scheduled__2024-11-25T10:30:00+00:00, state:running, queued_at: 2024-11-25 11:00:01.158620+00:00. externally triggered: False>
[2024-11-25T11:02:12.812+0000] {logging_mixin.py:190} INFO - Failure caused by list index out of range
[2024-11-25T11:02:12.813+0000] {taskinstance.py:1225} INFO - Marking task as UP_FOR_RETRY. dag_id=get_gbif_data_atropelamento, task_id=process_data, run_id=scheduled__2024-11-25T10:30:00+00:00, execution_date=20241125T103000, start_date=20241125T110212, end_date=20241125T110212
[2024-11-25T11:02:12.832+0000] {taskinstance.py:340} INFO - ::group::Post task execution logs
[2024-11-25T11:02:12.833+0000] {standard_task_runner.py:124} ERROR - Failed to execute job 1349 for task process_data (list index out of range; 1263)
Traceback (most recent call last):
  File "/home/airflow/.local/lib/python3.12/site-packages/airflow/task/task_runner/standard_task_runner.py", line 117, in _start_by_fork
    ret = args.func(args, dag=self.dag)
          ^^^^^^^^^^^^^^^^^^^^^^^^^^^^^
  File "/home/airflow/.local/lib/python3.12/site-packages/airflow/cli/cli_config.py", line 49, in command
    return func(*args, **kwargs)
           ^^^^^^^^^^^^^^^^^^^^^
  File "/home/airflow/.local/lib/python3.12/site-packages/airflow/utils/cli.py", line 115, in wrapper
    return f(*args, **kwargs)
           ^^^^^^^^^^^^^^^^^^
  File "/home/airflow/.local/lib/python3.12/site-packages/airflow/cli/commands/task_command.py", line 483, in task_run
    task_return_code = _run_task_by_selected_method(args, _dag, ti)
                       ^^^^^^^^^^^^^^^^^^^^^^^^^^^^^^^^^^^^^^^^^^^^
  File "/home/airflow/.local/lib/python3.12/site-packages/airflow/cli/commands/task_command.py", line 256, in _run_task_by_selected_method
    return _run_raw_task(args, ti)
           ^^^^^^^^^^^^^^^^^^^^^^^
  File "/home/airflow/.local/lib/python3.12/site-packages/airflow/cli/commands/task_command.py", line 341, in _run_raw_task
    return ti._run_raw_task(
           ^^^^^^^^^^^^^^^^^
  File "/home/airflow/.local/lib/python3.12/site-packages/airflow/utils/session.py", line 97, in wrapper
    return func(*args, session=session, **kwargs)
           ^^^^^^^^^^^^^^^^^^^^^^^^^^^^^^^^^^^^^^
  File "/home/airflow/.local/lib/python3.12/site-packages/airflow/models/taskinstance.py", line 3004, in _run_raw_task
    return _run_raw_task(
           ^^^^^^^^^^^^^^
  File "/home/airflow/.local/lib/python3.12/site-packages/airflow/models/taskinstance.py", line 273, in _run_raw_task
    TaskInstance._execute_task_with_callbacks(
  File "/home/airflow/.local/lib/python3.12/site-packages/airflow/models/taskinstance.py", line 3158, in _execute_task_with_callbacks
    result = self._execute_task(context, task_orig)
             ^^^^^^^^^^^^^^^^^^^^^^^^^^^^^^^^^^^^^^
  File "/home/airflow/.local/lib/python3.12/site-packages/airflow/models/taskinstance.py", line 3182, in _execute_task
    return _execute_task(self, context, task_orig)
           ^^^^^^^^^^^^^^^^^^^^^^^^^^^^^^^^^^^^^^^
  File "/home/airflow/.local/lib/python3.12/site-packages/airflow/models/taskinstance.py", line 767, in _execute_task
    result = _execute_callable(context=context, **execute_callable_kwargs)
             ^^^^^^^^^^^^^^^^^^^^^^^^^^^^^^^^^^^^^^^^^^^^^^^^^^^^^^^^^^^^^
  File "/home/airflow/.local/lib/python3.12/site-packages/airflow/models/taskinstance.py", line 733, in _execute_callable
    return ExecutionCallableRunner(
           ^^^^^^^^^^^^^^^^^^^^^^^^
  File "/home/airflow/.local/lib/python3.12/site-packages/airflow/utils/operator_helpers.py", line 252, in run
    return self.func(*args, **kwargs)
           ^^^^^^^^^^^^^^^^^^^^^^^^^^
  File "/home/airflow/.local/lib/python3.12/site-packages/airflow/models/baseoperator.py", line 406, in wrapper
    return func(self, *args, **kwargs)
           ^^^^^^^^^^^^^^^^^^^^^^^^^^^
  File "/home/airflow/.local/lib/python3.12/site-packages/airflow/decorators/base.py", line 266, in execute
    return_value = super().execute(context)
                   ^^^^^^^^^^^^^^^^^^^^^^^^
  File "/home/airflow/.local/lib/python3.12/site-packages/airflow/models/baseoperator.py", line 406, in wrapper
    return func(self, *args, **kwargs)
           ^^^^^^^^^^^^^^^^^^^^^^^^^^^
  File "/home/airflow/.local/lib/python3.12/site-packages/airflow/operators/python.py", line 238, in execute
    return_value = self.execute_callable()
                   ^^^^^^^^^^^^^^^^^^^^^^^
  File "/home/airflow/.local/lib/python3.12/site-packages/airflow/operators/python.py", line 256, in execute_callable
    return runner.run(*self.op_args, **self.op_kwargs)
           ^^^^^^^^^^^^^^^^^^^^^^^^^^^^^^^^^^^^^^^^^^^
  File "/home/airflow/.local/lib/python3.12/site-packages/airflow/utils/operator_helpers.py", line 252, in run
    return self.func(*args, **kwargs)
           ^^^^^^^^^^^^^^^^^^^^^^^^^^
  File "/opt/airflow/dags/gbif_dag.py", line 262, in process_data
    writer = csv.DictWriter(csvfile, fieldnames=occurrences[0].keys())
                                                ~~~~~~~~~~~^^^
IndexError: list index out of range
[2024-11-25T11:02:12.866+0000] {local_task_job_runner.py:266} INFO - Task exited with return code 1
[2024-11-25T11:02:12.908+0000] {taskinstance.py:3900} INFO - 0 downstream tasks scheduled from follow-on schedule check
[2024-11-25T11:02:12.910+0000] {local_task_job_runner.py:245} INFO - ::endgroup::
