[2024-11-25T10:47:55.710+0000] {local_task_job_runner.py:123} INFO - ::group::Pre task execution logs
[2024-11-25T10:47:55.727+0000] {taskinstance.py:2612} INFO - Dependencies all met for dep_context=non-requeueable deps ti=<TaskInstance: get_inaturalist_data_atropelamento.save_data manual__2024-11-25T10:42:38.381444+00:00 [queued]>
[2024-11-25T10:47:55.734+0000] {taskinstance.py:2612} INFO - Dependencies all met for dep_context=requeueable deps ti=<TaskInstance: get_inaturalist_data_atropelamento.save_data manual__2024-11-25T10:42:38.381444+00:00 [queued]>
[2024-11-25T10:47:55.735+0000] {taskinstance.py:2865} INFO - Starting attempt 7 of 9
[2024-11-25T10:47:55.748+0000] {taskinstance.py:2888} INFO - Executing <Task(_PythonDecoratedOperator): save_data> on 2024-11-25 10:42:38.381444+00:00
[2024-11-25T10:47:55.755+0000] {warnings.py:112} WARNING - /home/***/.local/lib/python3.12/site-packages/***/task/task_runner/standard_task_runner.py:70: DeprecationWarning: This process (pid=935) is multi-threaded, use of fork() may lead to deadlocks in the child.
  pid = os.fork()

[2024-11-25T10:47:55.756+0000] {standard_task_runner.py:72} INFO - Started process 938 to run task
[2024-11-25T10:47:55.756+0000] {standard_task_runner.py:104} INFO - Running: ['***', 'tasks', 'run', 'get_inaturalist_data_atropelamento', 'save_data', 'manual__2024-11-25T10:42:38.381444+00:00', '--job-id', '1321', '--raw', '--subdir', 'DAGS_FOLDER/inaturalist_dag.py', '--cfg-path', '/tmp/tmpvtc8z3cz']
[2024-11-25T10:47:55.757+0000] {standard_task_runner.py:105} INFO - Job 1321: Subtask save_data
[2024-11-25T10:47:55.792+0000] {task_command.py:467} INFO - Running <TaskInstance: get_inaturalist_data_atropelamento.save_data manual__2024-11-25T10:42:38.381444+00:00 [running]> on host bedd18328759
[2024-11-25T10:47:55.934+0000] {taskinstance.py:3131} INFO - Exporting env vars: AIRFLOW_CTX_DAG_OWNER='***' AIRFLOW_CTX_DAG_ID='get_inaturalist_data_atropelamento' AIRFLOW_CTX_TASK_ID='save_data' AIRFLOW_CTX_EXECUTION_DATE='2024-11-25T10:42:38.381444+00:00' AIRFLOW_CTX_TRY_NUMBER='7' AIRFLOW_CTX_DAG_RUN_ID='manual__2024-11-25T10:42:38.381444+00:00'
[2024-11-25T10:47:55.935+0000] {logging_mixin.py:190} INFO - Task instance is in running state
[2024-11-25T10:47:55.936+0000] {logging_mixin.py:190} INFO -  Previous state of the Task instance: queued
[2024-11-25T10:47:55.936+0000] {logging_mixin.py:190} INFO - Current task name:save_data state:running start_date:2024-11-25 10:47:55.728090+00:00
[2024-11-25T10:47:55.936+0000] {logging_mixin.py:190} INFO - Dag name:get_inaturalist_data_atropelamento and current dag run status:running
[2024-11-25T10:47:55.937+0000] {taskinstance.py:731} INFO - ::endgroup::
[2024-11-25T10:47:55.952+0000] {logging_mixin.py:190} INFO - json body
[2024-11-25T10:47:56.072+0000] {logging_mixin.py:190} INFO -      observation_id  ... default_photo
0          15230959  ...           NaN
1          15473130  ...           NaN
2          27059390  ...           NaN
3          27650954  ...           NaN
4          29002568  ...           NaN
..              ...  ...           ...
157       242944938  ...           NaN
158       247132579  ...           NaN
159       247708931  ...           NaN
160       250750964  ...           NaN
161       250907087  ...           NaN

[162 rows x 21 columns]
[2024-11-25T10:47:56.084+0000] {logging_mixin.py:190} INFO - csv size 101740
[2024-11-25T10:47:56.088+0000] {taskinstance.py:3310} ERROR - Task failed with exception
Traceback (most recent call last):
  File "/home/airflow/.local/lib/python3.12/site-packages/airflow/models/taskinstance.py", line 767, in _execute_task
    result = _execute_callable(context=context, **execute_callable_kwargs)
             ^^^^^^^^^^^^^^^^^^^^^^^^^^^^^^^^^^^^^^^^^^^^^^^^^^^^^^^^^^^^^
  File "/home/airflow/.local/lib/python3.12/site-packages/airflow/models/taskinstance.py", line 733, in _execute_callable
    return ExecutionCallableRunner(
           ^^^^^^^^^^^^^^^^^^^^^^^^
  File "/home/airflow/.local/lib/python3.12/site-packages/airflow/utils/operator_helpers.py", line 252, in run
    return self.func(*args, **kwargs)
           ^^^^^^^^^^^^^^^^^^^^^^^^^^
  File "/home/airflow/.local/lib/python3.12/site-packages/airflow/models/baseoperator.py", line 406, in wrapper
    return func(self, *args, **kwargs)
           ^^^^^^^^^^^^^^^^^^^^^^^^^^^
  File "/home/airflow/.local/lib/python3.12/site-packages/airflow/decorators/base.py", line 266, in execute
    return_value = super().execute(context)
                   ^^^^^^^^^^^^^^^^^^^^^^^^
  File "/home/airflow/.local/lib/python3.12/site-packages/airflow/models/baseoperator.py", line 406, in wrapper
    return func(self, *args, **kwargs)
           ^^^^^^^^^^^^^^^^^^^^^^^^^^^
  File "/home/airflow/.local/lib/python3.12/site-packages/airflow/operators/python.py", line 238, in execute
    return_value = self.execute_callable()
                   ^^^^^^^^^^^^^^^^^^^^^^^
  File "/home/airflow/.local/lib/python3.12/site-packages/airflow/operators/python.py", line 256, in execute_callable
    return runner.run(*self.op_args, **self.op_kwargs)
           ^^^^^^^^^^^^^^^^^^^^^^^^^^^^^^^^^^^^^^^^^^^
  File "/home/airflow/.local/lib/python3.12/site-packages/airflow/utils/operator_helpers.py", line 252, in run
    return self.func(*args, **kwargs)
           ^^^^^^^^^^^^^^^^^^^^^^^^^^
  File "/opt/airflow/dags/inaturalist_dag.py", line 210, in save_data
    connector.upload_data(data=csv_bytes.read(),
                               ^^^^^^^^^^^^^^
AttributeError: 'bytes' object has no attribute 'read'
[2024-11-25T10:47:56.108+0000] {logging_mixin.py:190} INFO - Task instance in failure state
[2024-11-25T10:47:56.109+0000] {logging_mixin.py:190} INFO - Task start:2024-11-25 10:47:55.728090+00:00 end:2024-11-25 10:47:56.108096+00:00 duration:0.380006
[2024-11-25T10:47:56.109+0000] {logging_mixin.py:190} INFO - Task:<Task(_PythonDecoratedOperator): save_data> dag:<DAG: get_inaturalist_data_atropelamento> dagrun:<DagRun get_inaturalist_data_atropelamento @ 2024-11-25 10:42:38.381444+00:00: manual__2024-11-25T10:42:38.381444+00:00, state:running, queued_at: 2024-11-25 10:42:38.400446+00:00. externally triggered: True>
[2024-11-25T10:47:56.110+0000] {logging_mixin.py:190} INFO - Failure caused by 'bytes' object has no attribute 'read'
[2024-11-25T10:47:56.110+0000] {taskinstance.py:1225} INFO - Marking task as UP_FOR_RETRY. dag_id=get_inaturalist_data_atropelamento, task_id=save_data, run_id=manual__2024-11-25T10:42:38.381444+00:00, execution_date=20241125T104238, start_date=20241125T104755, end_date=20241125T104756
[2024-11-25T10:47:56.138+0000] {taskinstance.py:340} INFO - ::group::Post task execution logs
[2024-11-25T10:47:56.139+0000] {standard_task_runner.py:124} ERROR - Failed to execute job 1321 for task save_data ('bytes' object has no attribute 'read'; 938)
Traceback (most recent call last):
  File "/home/airflow/.local/lib/python3.12/site-packages/airflow/task/task_runner/standard_task_runner.py", line 117, in _start_by_fork
    ret = args.func(args, dag=self.dag)
          ^^^^^^^^^^^^^^^^^^^^^^^^^^^^^
  File "/home/airflow/.local/lib/python3.12/site-packages/airflow/cli/cli_config.py", line 49, in command
    return func(*args, **kwargs)
           ^^^^^^^^^^^^^^^^^^^^^
  File "/home/airflow/.local/lib/python3.12/site-packages/airflow/utils/cli.py", line 115, in wrapper
    return f(*args, **kwargs)
           ^^^^^^^^^^^^^^^^^^
  File "/home/airflow/.local/lib/python3.12/site-packages/airflow/cli/commands/task_command.py", line 483, in task_run
    task_return_code = _run_task_by_selected_method(args, _dag, ti)
                       ^^^^^^^^^^^^^^^^^^^^^^^^^^^^^^^^^^^^^^^^^^^^
  File "/home/airflow/.local/lib/python3.12/site-packages/airflow/cli/commands/task_command.py", line 256, in _run_task_by_selected_method
    return _run_raw_task(args, ti)
           ^^^^^^^^^^^^^^^^^^^^^^^
  File "/home/airflow/.local/lib/python3.12/site-packages/airflow/cli/commands/task_command.py", line 341, in _run_raw_task
    return ti._run_raw_task(
           ^^^^^^^^^^^^^^^^^
  File "/home/airflow/.local/lib/python3.12/site-packages/airflow/utils/session.py", line 97, in wrapper
    return func(*args, session=session, **kwargs)
           ^^^^^^^^^^^^^^^^^^^^^^^^^^^^^^^^^^^^^^
  File "/home/airflow/.local/lib/python3.12/site-packages/airflow/models/taskinstance.py", line 3004, in _run_raw_task
    return _run_raw_task(
           ^^^^^^^^^^^^^^
  File "/home/airflow/.local/lib/python3.12/site-packages/airflow/models/taskinstance.py", line 273, in _run_raw_task
    TaskInstance._execute_task_with_callbacks(
  File "/home/airflow/.local/lib/python3.12/site-packages/airflow/models/taskinstance.py", line 3158, in _execute_task_with_callbacks
    result = self._execute_task(context, task_orig)
             ^^^^^^^^^^^^^^^^^^^^^^^^^^^^^^^^^^^^^^
  File "/home/airflow/.local/lib/python3.12/site-packages/airflow/models/taskinstance.py", line 3182, in _execute_task
    return _execute_task(self, context, task_orig)
           ^^^^^^^^^^^^^^^^^^^^^^^^^^^^^^^^^^^^^^^
  File "/home/airflow/.local/lib/python3.12/site-packages/airflow/models/taskinstance.py", line 767, in _execute_task
    result = _execute_callable(context=context, **execute_callable_kwargs)
             ^^^^^^^^^^^^^^^^^^^^^^^^^^^^^^^^^^^^^^^^^^^^^^^^^^^^^^^^^^^^^
  File "/home/airflow/.local/lib/python3.12/site-packages/airflow/models/taskinstance.py", line 733, in _execute_callable
    return ExecutionCallableRunner(
           ^^^^^^^^^^^^^^^^^^^^^^^^
  File "/home/airflow/.local/lib/python3.12/site-packages/airflow/utils/operator_helpers.py", line 252, in run
    return self.func(*args, **kwargs)
           ^^^^^^^^^^^^^^^^^^^^^^^^^^
  File "/home/airflow/.local/lib/python3.12/site-packages/airflow/models/baseoperator.py", line 406, in wrapper
    return func(self, *args, **kwargs)
           ^^^^^^^^^^^^^^^^^^^^^^^^^^^
  File "/home/airflow/.local/lib/python3.12/site-packages/airflow/decorators/base.py", line 266, in execute
    return_value = super().execute(context)
                   ^^^^^^^^^^^^^^^^^^^^^^^^
  File "/home/airflow/.local/lib/python3.12/site-packages/airflow/models/baseoperator.py", line 406, in wrapper
    return func(self, *args, **kwargs)
           ^^^^^^^^^^^^^^^^^^^^^^^^^^^
  File "/home/airflow/.local/lib/python3.12/site-packages/airflow/operators/python.py", line 238, in execute
    return_value = self.execute_callable()
                   ^^^^^^^^^^^^^^^^^^^^^^^
  File "/home/airflow/.local/lib/python3.12/site-packages/airflow/operators/python.py", line 256, in execute_callable
    return runner.run(*self.op_args, **self.op_kwargs)
           ^^^^^^^^^^^^^^^^^^^^^^^^^^^^^^^^^^^^^^^^^^^
  File "/home/airflow/.local/lib/python3.12/site-packages/airflow/utils/operator_helpers.py", line 252, in run
    return self.func(*args, **kwargs)
           ^^^^^^^^^^^^^^^^^^^^^^^^^^
  File "/opt/airflow/dags/inaturalist_dag.py", line 210, in save_data
    connector.upload_data(data=csv_bytes.read(),
                               ^^^^^^^^^^^^^^
AttributeError: 'bytes' object has no attribute 'read'
[2024-11-25T10:47:56.171+0000] {local_task_job_runner.py:266} INFO - Task exited with return code 1
[2024-11-25T10:47:56.197+0000] {taskinstance.py:3900} INFO - 0 downstream tasks scheduled from follow-on schedule check
[2024-11-25T10:47:56.201+0000] {local_task_job_runner.py:245} INFO - ::endgroup::
