[2024-11-21T16:11:42.227+0000] {local_task_job_runner.py:123} INFO - ::group::Pre task execution logs
[2024-11-21T16:11:42.241+0000] {taskinstance.py:2612} INFO - Dependencies all met for dep_context=non-requeueable deps ti=<TaskInstance: get_gbif_data_atropelamento.publish_message_for_transformation manual__2024-11-21T15:37:22.095152+00:00 [queued]>
[2024-11-21T16:11:42.247+0000] {taskinstance.py:2612} INFO - Dependencies all met for dep_context=requeueable deps ti=<TaskInstance: get_gbif_data_atropelamento.publish_message_for_transformation manual__2024-11-21T15:37:22.095152+00:00 [queued]>
[2024-11-21T16:11:42.247+0000] {taskinstance.py:2865} INFO - Starting attempt 24 of 25
[2024-11-21T16:11:42.258+0000] {taskinstance.py:2888} INFO - Executing <Task(_PythonDecoratedOperator): publish_message_for_transformation> on 2024-11-21 15:37:22.095152+00:00
[2024-11-21T16:11:42.269+0000] {warnings.py:112} WARNING - /home/***/.local/lib/python3.12/site-packages/***/task/task_runner/standard_task_runner.py:70: DeprecationWarning: This process (pid=1085) is multi-threaded, use of fork() may lead to deadlocks in the child.
  pid = os.fork()

[2024-11-21T16:11:42.270+0000] {standard_task_runner.py:72} INFO - Started process 1088 to run task
[2024-11-21T16:11:42.271+0000] {standard_task_runner.py:104} INFO - Running: ['***', 'tasks', 'run', 'get_gbif_data_atropelamento', 'publish_message_for_transformation', 'manual__2024-11-21T15:37:22.095152+00:00', '--job-id', '973', '--raw', '--subdir', 'DAGS_FOLDER/gbif_dag.py', '--cfg-path', '/tmp/tmpdkwhvkkz']
[2024-11-21T16:11:42.271+0000] {standard_task_runner.py:105} INFO - Job 973: Subtask publish_message_for_transformation
[2024-11-21T16:11:42.306+0000] {task_command.py:467} INFO - Running <TaskInstance: get_gbif_data_atropelamento.publish_message_for_transformation manual__2024-11-21T15:37:22.095152+00:00 [running]> on host 569dbdc45a07
[2024-11-21T16:11:42.390+0000] {taskinstance.py:3131} INFO - Exporting env vars: AIRFLOW_CTX_DAG_OWNER='***' AIRFLOW_CTX_DAG_ID='get_gbif_data_atropelamento' AIRFLOW_CTX_TASK_ID='publish_message_for_transformation' AIRFLOW_CTX_EXECUTION_DATE='2024-11-21T15:37:22.095152+00:00' AIRFLOW_CTX_TRY_NUMBER='24' AIRFLOW_CTX_DAG_RUN_ID='manual__2024-11-21T15:37:22.095152+00:00'
[2024-11-21T16:11:42.391+0000] {logging_mixin.py:190} INFO - Task instance is in running state
[2024-11-21T16:11:42.392+0000] {logging_mixin.py:190} INFO -  Previous state of the Task instance: queued
[2024-11-21T16:11:42.392+0000] {logging_mixin.py:190} INFO - Current task name:publish_message_for_transformation state:running start_date:2024-11-21 16:11:42.241359+00:00
[2024-11-21T16:11:42.392+0000] {logging_mixin.py:190} INFO - Dag name:get_gbif_data_atropelamento and current dag run status:running
[2024-11-21T16:11:42.393+0000] {taskinstance.py:731} INFO - ::endgroup::
[2024-11-21T16:11:42.394+0000] {logging_mixin.py:190} INFO - sending message of path:gbif_data/atropelamento_data/2024/11/21/atropelamento_occurrences_153736.csv
[2024-11-21T16:11:42.396+0000] {connection_workflow.py:179} INFO - Pika version 1.3.2 connecting to ('192.168.30.21', 5672)
[2024-11-21T16:11:42.417+0000] {io_services_utils.py:349} ERROR - Socket failed to connect: <socket.socket fd=93, family=2, type=1, proto=6, laddr=('172.20.0.6', 51128)>; error=111 (Connection refused)
[2024-11-21T16:11:42.417+0000] {connection_workflow.py:375} ERROR - TCP Connection attempt failed: ConnectionRefusedError(111, 'Connection refused'); dest=(2, 1, 6, '', ('192.168.30.21', 5672))
[2024-11-21T16:11:42.417+0000] {connection_workflow.py:291} ERROR - AMQPConnector - reporting failure: AMQPConnectorSocketConnectError: ConnectionRefusedError(111, 'Connection refused')
[2024-11-21T16:11:42.419+0000] {connection_workflow.py:746} ERROR - AMQP connection workflow failed: AMQPConnectionWorkflowFailed: 1 exceptions in all; last exception - AMQPConnectorSocketConnectError: ConnectionRefusedError(111, 'Connection refused'); first exception - None.
[2024-11-21T16:11:42.419+0000] {connection_workflow.py:723} ERROR - AMQPConnectionWorkflow - reporting failure: AMQPConnectionWorkflowFailed: 1 exceptions in all; last exception - AMQPConnectorSocketConnectError: ConnectionRefusedError(111, 'Connection refused'); first exception - None
[2024-11-21T16:11:42.419+0000] {blocking_connection.py:450} ERROR - Connection workflow failed: AMQPConnectionWorkflowFailed: 1 exceptions in all; last exception - AMQPConnectorSocketConnectError: ConnectionRefusedError(111, 'Connection refused'); first exception - None
[2024-11-21T16:11:42.420+0000] {blocking_connection.py:457} ERROR - Error in _create_connection().
Traceback (most recent call last):
  File "/home/airflow/.local/lib/python3.12/site-packages/pika/adapters/blocking_connection.py", line 451, in _create_connection
    raise self._reap_last_connection_workflow_error(error)
pika.exceptions.AMQPConnectionError
[2024-11-21T16:11:42.421+0000] {taskinstance.py:3310} ERROR - Task failed with exception
Traceback (most recent call last):
  File "/home/airflow/.local/lib/python3.12/site-packages/airflow/models/taskinstance.py", line 767, in _execute_task
    result = _execute_callable(context=context, **execute_callable_kwargs)
             ^^^^^^^^^^^^^^^^^^^^^^^^^^^^^^^^^^^^^^^^^^^^^^^^^^^^^^^^^^^^^
  File "/home/airflow/.local/lib/python3.12/site-packages/airflow/models/taskinstance.py", line 733, in _execute_callable
    return ExecutionCallableRunner(
           ^^^^^^^^^^^^^^^^^^^^^^^^
  File "/home/airflow/.local/lib/python3.12/site-packages/airflow/utils/operator_helpers.py", line 252, in run
    return self.func(*args, **kwargs)
           ^^^^^^^^^^^^^^^^^^^^^^^^^^
  File "/home/airflow/.local/lib/python3.12/site-packages/airflow/models/baseoperator.py", line 406, in wrapper
    return func(self, *args, **kwargs)
           ^^^^^^^^^^^^^^^^^^^^^^^^^^^
  File "/home/airflow/.local/lib/python3.12/site-packages/airflow/decorators/base.py", line 266, in execute
    return_value = super().execute(context)
                   ^^^^^^^^^^^^^^^^^^^^^^^^
  File "/home/airflow/.local/lib/python3.12/site-packages/airflow/models/baseoperator.py", line 406, in wrapper
    return func(self, *args, **kwargs)
           ^^^^^^^^^^^^^^^^^^^^^^^^^^^
  File "/home/airflow/.local/lib/python3.12/site-packages/airflow/operators/python.py", line 238, in execute
    return_value = self.execute_callable()
                   ^^^^^^^^^^^^^^^^^^^^^^^
  File "/home/airflow/.local/lib/python3.12/site-packages/airflow/operators/python.py", line 256, in execute_callable
    return runner.run(*self.op_args, **self.op_kwargs)
           ^^^^^^^^^^^^^^^^^^^^^^^^^^^^^^^^^^^^^^^^^^^
  File "/home/airflow/.local/lib/python3.12/site-packages/airflow/utils/operator_helpers.py", line 252, in run
    return self.func(*args, **kwargs)
           ^^^^^^^^^^^^^^^^^^^^^^^^^^
  File "/opt/airflow/dags/gbif_dag.py", line 288, in publish_message_for_transformation
    producer.publish_message(message=path)
  File "/opt/airflow/connectors/rabbitmq.py", line 19, in publish_message
    connection = pika.BlockingConnection(pika.ConnectionParameters(host='192.168.30.21'))
                 ^^^^^^^^^^^^^^^^^^^^^^^^^^^^^^^^^^^^^^^^^^^^^^^^^^^^^^^^^^^^^^^^^^^^^^^^
  File "/home/airflow/.local/lib/python3.12/site-packages/pika/adapters/blocking_connection.py", line 360, in __init__
    self._impl = self._create_connection(parameters, _impl_class)
                 ^^^^^^^^^^^^^^^^^^^^^^^^^^^^^^^^^^^^^^^^^^^^^^^^
  File "/home/airflow/.local/lib/python3.12/site-packages/pika/adapters/blocking_connection.py", line 451, in _create_connection
    raise self._reap_last_connection_workflow_error(error)
pika.exceptions.AMQPConnectionError
[2024-11-21T16:11:42.437+0000] {logging_mixin.py:190} INFO - Task instance in failure state
[2024-11-21T16:11:42.438+0000] {logging_mixin.py:190} INFO - Task start:2024-11-21 16:11:42.241359+00:00 end:2024-11-21 16:11:42.437064+00:00 duration:0.195705
[2024-11-21T16:11:42.438+0000] {logging_mixin.py:190} INFO - Task:<Task(_PythonDecoratedOperator): publish_message_for_transformation> dag:<DAG: get_gbif_data_atropelamento> dagrun:<DagRun get_gbif_data_atropelamento @ 2024-11-21 15:37:22.095152+00:00: manual__2024-11-21T15:37:22.095152+00:00, state:running, queued_at: 2024-11-21 16:08:54.494626+00:00. externally triggered: True>
[2024-11-21T16:11:42.438+0000] {logging_mixin.py:190} INFO - Failure caused by 
[2024-11-21T16:11:42.438+0000] {taskinstance.py:1225} INFO - Marking task as UP_FOR_RETRY. dag_id=get_gbif_data_atropelamento, task_id=publish_message_for_transformation, run_id=manual__2024-11-21T15:37:22.095152+00:00, execution_date=20241121T153722, start_date=20241121T161142, end_date=20241121T161142
[2024-11-21T16:11:42.454+0000] {taskinstance.py:340} INFO - ::group::Post task execution logs
[2024-11-21T16:11:42.454+0000] {standard_task_runner.py:124} ERROR - Failed to execute job 973 for task publish_message_for_transformation (; 1088)
Traceback (most recent call last):
  File "/home/airflow/.local/lib/python3.12/site-packages/airflow/task/task_runner/standard_task_runner.py", line 117, in _start_by_fork
    ret = args.func(args, dag=self.dag)
          ^^^^^^^^^^^^^^^^^^^^^^^^^^^^^
  File "/home/airflow/.local/lib/python3.12/site-packages/airflow/cli/cli_config.py", line 49, in command
    return func(*args, **kwargs)
           ^^^^^^^^^^^^^^^^^^^^^
  File "/home/airflow/.local/lib/python3.12/site-packages/airflow/utils/cli.py", line 115, in wrapper
    return f(*args, **kwargs)
           ^^^^^^^^^^^^^^^^^^
  File "/home/airflow/.local/lib/python3.12/site-packages/airflow/cli/commands/task_command.py", line 483, in task_run
    task_return_code = _run_task_by_selected_method(args, _dag, ti)
                       ^^^^^^^^^^^^^^^^^^^^^^^^^^^^^^^^^^^^^^^^^^^^
  File "/home/airflow/.local/lib/python3.12/site-packages/airflow/cli/commands/task_command.py", line 256, in _run_task_by_selected_method
    return _run_raw_task(args, ti)
           ^^^^^^^^^^^^^^^^^^^^^^^
  File "/home/airflow/.local/lib/python3.12/site-packages/airflow/cli/commands/task_command.py", line 341, in _run_raw_task
    return ti._run_raw_task(
           ^^^^^^^^^^^^^^^^^
  File "/home/airflow/.local/lib/python3.12/site-packages/airflow/utils/session.py", line 97, in wrapper
    return func(*args, session=session, **kwargs)
           ^^^^^^^^^^^^^^^^^^^^^^^^^^^^^^^^^^^^^^
  File "/home/airflow/.local/lib/python3.12/site-packages/airflow/models/taskinstance.py", line 3004, in _run_raw_task
    return _run_raw_task(
           ^^^^^^^^^^^^^^
  File "/home/airflow/.local/lib/python3.12/site-packages/airflow/models/taskinstance.py", line 273, in _run_raw_task
    TaskInstance._execute_task_with_callbacks(
  File "/home/airflow/.local/lib/python3.12/site-packages/airflow/models/taskinstance.py", line 3158, in _execute_task_with_callbacks
    result = self._execute_task(context, task_orig)
             ^^^^^^^^^^^^^^^^^^^^^^^^^^^^^^^^^^^^^^
  File "/home/airflow/.local/lib/python3.12/site-packages/airflow/models/taskinstance.py", line 3182, in _execute_task
    return _execute_task(self, context, task_orig)
           ^^^^^^^^^^^^^^^^^^^^^^^^^^^^^^^^^^^^^^^
  File "/home/airflow/.local/lib/python3.12/site-packages/airflow/models/taskinstance.py", line 767, in _execute_task
    result = _execute_callable(context=context, **execute_callable_kwargs)
             ^^^^^^^^^^^^^^^^^^^^^^^^^^^^^^^^^^^^^^^^^^^^^^^^^^^^^^^^^^^^^
  File "/home/airflow/.local/lib/python3.12/site-packages/airflow/models/taskinstance.py", line 733, in _execute_callable
    return ExecutionCallableRunner(
           ^^^^^^^^^^^^^^^^^^^^^^^^
  File "/home/airflow/.local/lib/python3.12/site-packages/airflow/utils/operator_helpers.py", line 252, in run
    return self.func(*args, **kwargs)
           ^^^^^^^^^^^^^^^^^^^^^^^^^^
  File "/home/airflow/.local/lib/python3.12/site-packages/airflow/models/baseoperator.py", line 406, in wrapper
    return func(self, *args, **kwargs)
           ^^^^^^^^^^^^^^^^^^^^^^^^^^^
  File "/home/airflow/.local/lib/python3.12/site-packages/airflow/decorators/base.py", line 266, in execute
    return_value = super().execute(context)
                   ^^^^^^^^^^^^^^^^^^^^^^^^
  File "/home/airflow/.local/lib/python3.12/site-packages/airflow/models/baseoperator.py", line 406, in wrapper
    return func(self, *args, **kwargs)
           ^^^^^^^^^^^^^^^^^^^^^^^^^^^
  File "/home/airflow/.local/lib/python3.12/site-packages/airflow/operators/python.py", line 238, in execute
    return_value = self.execute_callable()
                   ^^^^^^^^^^^^^^^^^^^^^^^
  File "/home/airflow/.local/lib/python3.12/site-packages/airflow/operators/python.py", line 256, in execute_callable
    return runner.run(*self.op_args, **self.op_kwargs)
           ^^^^^^^^^^^^^^^^^^^^^^^^^^^^^^^^^^^^^^^^^^^
  File "/home/airflow/.local/lib/python3.12/site-packages/airflow/utils/operator_helpers.py", line 252, in run
    return self.func(*args, **kwargs)
           ^^^^^^^^^^^^^^^^^^^^^^^^^^
  File "/opt/airflow/dags/gbif_dag.py", line 288, in publish_message_for_transformation
    producer.publish_message(message=path)
  File "/opt/airflow/connectors/rabbitmq.py", line 19, in publish_message
    connection = pika.BlockingConnection(pika.ConnectionParameters(host='192.168.30.21'))
                 ^^^^^^^^^^^^^^^^^^^^^^^^^^^^^^^^^^^^^^^^^^^^^^^^^^^^^^^^^^^^^^^^^^^^^^^^
  File "/home/airflow/.local/lib/python3.12/site-packages/pika/adapters/blocking_connection.py", line 360, in __init__
    self._impl = self._create_connection(parameters, _impl_class)
                 ^^^^^^^^^^^^^^^^^^^^^^^^^^^^^^^^^^^^^^^^^^^^^^^^
  File "/home/airflow/.local/lib/python3.12/site-packages/pika/adapters/blocking_connection.py", line 451, in _create_connection
    raise self._reap_last_connection_workflow_error(error)
pika.exceptions.AMQPConnectionError
[2024-11-21T16:11:42.484+0000] {local_task_job_runner.py:266} INFO - Task exited with return code 1
[2024-11-21T16:11:42.497+0000] {taskinstance.py:3900} INFO - 0 downstream tasks scheduled from follow-on schedule check
[2024-11-21T16:11:42.498+0000] {local_task_job_runner.py:245} INFO - ::endgroup::
