[2024-11-19T10:56:39.634+0000] {local_task_job_runner.py:123} INFO - ::group::Pre task execution logs
[2024-11-19T10:56:39.651+0000] {taskinstance.py:2612} INFO - Dependencies all met for dep_context=non-requeueable deps ti=<TaskInstance: get_inaturalist_data_atropelada.get_all_data scheduled__2024-11-19T10:00:00+00:00 [queued]>
[2024-11-19T10:56:39.661+0000] {taskinstance.py:2612} INFO - Dependencies all met for dep_context=requeueable deps ti=<TaskInstance: get_inaturalist_data_atropelada.get_all_data scheduled__2024-11-19T10:00:00+00:00 [queued]>
[2024-11-19T10:56:39.661+0000] {taskinstance.py:2865} INFO - Starting attempt 4 of 4
[2024-11-19T10:56:39.674+0000] {taskinstance.py:2888} INFO - Executing <Task(_PythonDecoratedOperator): get_all_data> on 2024-11-19 10:00:00+00:00
[2024-11-19T10:56:39.682+0000] {warnings.py:112} WARNING - /home/***/.local/lib/python3.12/site-packages/***/task/task_runner/standard_task_runner.py:70: DeprecationWarning: This process (pid=205) is multi-threaded, use of fork() may lead to deadlocks in the child.
  pid = os.fork()

[2024-11-19T10:56:39.683+0000] {standard_task_runner.py:72} INFO - Started process 210 to run task
[2024-11-19T10:56:39.684+0000] {standard_task_runner.py:104} INFO - Running: ['***', 'tasks', 'run', 'get_inaturalist_data_atropelada', 'get_all_data', 'scheduled__2024-11-19T10:00:00+00:00', '--job-id', '698', '--raw', '--subdir', 'DAGS_FOLDER/inaturalist_dag.py', '--cfg-path', '/tmp/tmpe5899sw5']
[2024-11-19T10:56:39.685+0000] {standard_task_runner.py:105} INFO - Job 698: Subtask get_all_data
[2024-11-19T10:56:39.731+0000] {task_command.py:467} INFO - Running <TaskInstance: get_inaturalist_data_atropelada.get_all_data scheduled__2024-11-19T10:00:00+00:00 [running]> on host 1bd5b698e8d7
[2024-11-19T10:56:39.844+0000] {taskinstance.py:3131} INFO - Exporting env vars: AIRFLOW_CTX_DAG_OWNER='***' AIRFLOW_CTX_DAG_ID='get_inaturalist_data_atropelada' AIRFLOW_CTX_TASK_ID='get_all_data' AIRFLOW_CTX_EXECUTION_DATE='2024-11-19T10:00:00+00:00' AIRFLOW_CTX_TRY_NUMBER='4' AIRFLOW_CTX_DAG_RUN_ID='scheduled__2024-11-19T10:00:00+00:00'
[2024-11-19T10:56:39.846+0000] {logging_mixin.py:190} INFO - Task instance is in running state
[2024-11-19T10:56:39.846+0000] {logging_mixin.py:190} INFO -  Previous state of the Task instance: queued
[2024-11-19T10:56:39.846+0000] {logging_mixin.py:190} INFO - Current task name:get_all_data state:running start_date:2024-11-19 10:56:39.651481+00:00
[2024-11-19T10:56:39.847+0000] {logging_mixin.py:190} INFO - Dag name:get_inaturalist_data_atropelada and current dag run status:running
[2024-11-19T10:56:39.847+0000] {taskinstance.py:731} INFO - ::endgroup::
[2024-11-19T10:56:39.847+0000] {inaturalist_dag.py:129} INFO - Getting data from keyword: atropelada
[2024-11-19T10:56:40.906+0000] {taskinstance.py:3310} ERROR - Task failed with exception
Traceback (most recent call last):
  File "/home/airflow/.local/lib/python3.12/site-packages/urllib3/connection.py", line 196, in _new_conn
    sock = connection.create_connection(
           ^^^^^^^^^^^^^^^^^^^^^^^^^^^^^
  File "/home/airflow/.local/lib/python3.12/site-packages/urllib3/util/connection.py", line 85, in create_connection
    raise err
  File "/home/airflow/.local/lib/python3.12/site-packages/urllib3/util/connection.py", line 73, in create_connection
    sock.connect(sa)
OSError: [Errno 101] Network is unreachable

The above exception was the direct cause of the following exception:

Traceback (most recent call last):
  File "/home/airflow/.local/lib/python3.12/site-packages/urllib3/connectionpool.py", line 789, in urlopen
    response = self._make_request(
               ^^^^^^^^^^^^^^^^^^^
  File "/home/airflow/.local/lib/python3.12/site-packages/urllib3/connectionpool.py", line 490, in _make_request
    raise new_e
  File "/home/airflow/.local/lib/python3.12/site-packages/urllib3/connectionpool.py", line 466, in _make_request
    self._validate_conn(conn)
  File "/home/airflow/.local/lib/python3.12/site-packages/urllib3/connectionpool.py", line 1095, in _validate_conn
    conn.connect()
  File "/home/airflow/.local/lib/python3.12/site-packages/urllib3/connection.py", line 615, in connect
    self.sock = sock = self._new_conn()
                       ^^^^^^^^^^^^^^^^
  File "/home/airflow/.local/lib/python3.12/site-packages/urllib3/connection.py", line 211, in _new_conn
    raise NewConnectionError(
urllib3.exceptions.NewConnectionError: <urllib3.connection.HTTPSConnection object at 0x7cb79c173590>: Failed to establish a new connection: [Errno 101] Network is unreachable

The above exception was the direct cause of the following exception:

Traceback (most recent call last):
  File "/home/airflow/.local/lib/python3.12/site-packages/requests/adapters.py", line 667, in send
    resp = conn.urlopen(
           ^^^^^^^^^^^^^
  File "/home/airflow/.local/lib/python3.12/site-packages/urllib3/connectionpool.py", line 843, in urlopen
    retries = retries.increment(
              ^^^^^^^^^^^^^^^^^^
  File "/home/airflow/.local/lib/python3.12/site-packages/urllib3/util/retry.py", line 519, in increment
    raise MaxRetryError(_pool, url, reason) from reason  # type: ignore[arg-type]
    ^^^^^^^^^^^^^^^^^^^^^^^^^^^^^^^^^^^^^^^^^^^^^^^^^^^
urllib3.exceptions.MaxRetryError: HTTPSConnectionPool(host='api.inaturalist.org', port=443): Max retries exceeded with url: /v1/observations?geo=true&iconic_taxa=Amphibia%2CAves%2CMammalia%2CReptilia%2Cunknown&id_above=18733787&q=atropelada&page=1&per_page=5&order=asc&order_by=id (Caused by NewConnectionError('<urllib3.connection.HTTPSConnection object at 0x7cb79c173590>: Failed to establish a new connection: [Errno 101] Network is unreachable'))

During handling of the above exception, another exception occurred:

Traceback (most recent call last):
  File "/home/airflow/.local/lib/python3.12/site-packages/airflow/models/taskinstance.py", line 767, in _execute_task
    result = _execute_callable(context=context, **execute_callable_kwargs)
             ^^^^^^^^^^^^^^^^^^^^^^^^^^^^^^^^^^^^^^^^^^^^^^^^^^^^^^^^^^^^^
  File "/home/airflow/.local/lib/python3.12/site-packages/airflow/models/taskinstance.py", line 733, in _execute_callable
    return ExecutionCallableRunner(
           ^^^^^^^^^^^^^^^^^^^^^^^^
  File "/home/airflow/.local/lib/python3.12/site-packages/airflow/utils/operator_helpers.py", line 252, in run
    return self.func(*args, **kwargs)
           ^^^^^^^^^^^^^^^^^^^^^^^^^^
  File "/home/airflow/.local/lib/python3.12/site-packages/airflow/models/baseoperator.py", line 406, in wrapper
    return func(self, *args, **kwargs)
           ^^^^^^^^^^^^^^^^^^^^^^^^^^^
  File "/home/airflow/.local/lib/python3.12/site-packages/airflow/decorators/base.py", line 266, in execute
    return_value = super().execute(context)
                   ^^^^^^^^^^^^^^^^^^^^^^^^
  File "/home/airflow/.local/lib/python3.12/site-packages/airflow/models/baseoperator.py", line 406, in wrapper
    return func(self, *args, **kwargs)
           ^^^^^^^^^^^^^^^^^^^^^^^^^^^
  File "/home/airflow/.local/lib/python3.12/site-packages/airflow/operators/python.py", line 238, in execute
    return_value = self.execute_callable()
                   ^^^^^^^^^^^^^^^^^^^^^^^
  File "/home/airflow/.local/lib/python3.12/site-packages/airflow/operators/python.py", line 256, in execute_callable
    return runner.run(*self.op_args, **self.op_kwargs)
           ^^^^^^^^^^^^^^^^^^^^^^^^^^^^^^^^^^^^^^^^^^^
  File "/home/airflow/.local/lib/python3.12/site-packages/airflow/utils/operator_helpers.py", line 252, in run
    return self.func(*args, **kwargs)
           ^^^^^^^^^^^^^^^^^^^^^^^^^^
  File "/opt/airflow/dags/inaturalist_dag.py", line 132, in get_all_data
    last_observation_id, observations_extracted = get_data(maximum_id)
                                                  ^^^^^^^^^^^^^^^^^^^^
  File "/opt/airflow/dags/inaturalist_dag.py", line 61, in get_data
    response = requests.get(API_URL, params=params)
               ^^^^^^^^^^^^^^^^^^^^^^^^^^^^^^^^^^^^
  File "/home/airflow/.local/lib/python3.12/site-packages/requests/api.py", line 73, in get
    return request("get", url, params=params, **kwargs)
           ^^^^^^^^^^^^^^^^^^^^^^^^^^^^^^^^^^^^^^^^^^^^
  File "/home/airflow/.local/lib/python3.12/site-packages/requests/api.py", line 59, in request
    return session.request(method=method, url=url, **kwargs)
           ^^^^^^^^^^^^^^^^^^^^^^^^^^^^^^^^^^^^^^^^^^^^^^^^^
  File "/home/airflow/.local/lib/python3.12/site-packages/requests/sessions.py", line 589, in request
    resp = self.send(prep, **send_kwargs)
           ^^^^^^^^^^^^^^^^^^^^^^^^^^^^^^
  File "/home/airflow/.local/lib/python3.12/site-packages/requests/sessions.py", line 703, in send
    r = adapter.send(request, **kwargs)
        ^^^^^^^^^^^^^^^^^^^^^^^^^^^^^^^
  File "/home/airflow/.local/lib/python3.12/site-packages/requests/adapters.py", line 700, in send
    raise ConnectionError(e, request=request)
requests.exceptions.ConnectionError: HTTPSConnectionPool(host='api.inaturalist.org', port=443): Max retries exceeded with url: /v1/observations?geo=true&iconic_taxa=Amphibia%2CAves%2CMammalia%2CReptilia%2Cunknown&id_above=18733787&q=atropelada&page=1&per_page=5&order=asc&order_by=id (Caused by NewConnectionError('<urllib3.connection.HTTPSConnection object at 0x7cb79c173590>: Failed to establish a new connection: [Errno 101] Network is unreachable'))
[2024-11-19T10:56:40.924+0000] {logging_mixin.py:190} INFO - Task instance in failure state
[2024-11-19T10:56:40.925+0000] {logging_mixin.py:190} INFO - Task start:2024-11-19 10:56:39.651481+00:00 end:2024-11-19 10:56:40.924265+00:00 duration:1.272784
[2024-11-19T10:56:40.926+0000] {logging_mixin.py:190} INFO - Task:<Task(_PythonDecoratedOperator): get_all_data> dag:<DAG: get_inaturalist_data_atropelada> dagrun:<DagRun get_inaturalist_data_atropelada @ 2024-11-19 10:00:00+00:00: scheduled__2024-11-19T10:00:00+00:00, state:running, queued_at: 2024-11-19 10:52:43.809725+00:00. externally triggered: False>
[2024-11-19T10:56:40.926+0000] {logging_mixin.py:190} INFO - Failure caused by HTTPSConnectionPool(host='api.inaturalist.org', port=443): Max retries exceeded with url: /v1/observations?geo=true&iconic_taxa=Amphibia%2CAves%2CMammalia%2CReptilia%2Cunknown&id_above=18733787&q=atropelada&page=1&per_page=5&order=asc&order_by=id (Caused by NewConnectionError('<urllib3.connection.HTTPSConnection object at 0x7cb79c173590>: Failed to establish a new connection: [Errno 101] Network is unreachable'))
[2024-11-19T10:56:40.927+0000] {taskinstance.py:1225} INFO - Marking task as FAILED. dag_id=get_inaturalist_data_atropelada, task_id=get_all_data, run_id=scheduled__2024-11-19T10:00:00+00:00, execution_date=20241119T100000, start_date=20241119T105639, end_date=20241119T105640
[2024-11-19T10:56:40.947+0000] {taskinstance.py:340} INFO - ::group::Post task execution logs
[2024-11-19T10:56:40.948+0000] {standard_task_runner.py:124} ERROR - Failed to execute job 698 for task get_all_data (HTTPSConnectionPool(host='api.inaturalist.org', port=443): Max retries exceeded with url: /v1/observations?geo=true&iconic_taxa=Amphibia%2CAves%2CMammalia%2CReptilia%2Cunknown&id_above=18733787&q=atropelada&page=1&per_page=5&order=asc&order_by=id (Caused by NewConnectionError('<urllib3.connection.HTTPSConnection object at 0x7cb79c173590>: Failed to establish a new connection: [Errno 101] Network is unreachable')); 210)
Traceback (most recent call last):
  File "/home/airflow/.local/lib/python3.12/site-packages/urllib3/connection.py", line 196, in _new_conn
    sock = connection.create_connection(
           ^^^^^^^^^^^^^^^^^^^^^^^^^^^^^
  File "/home/airflow/.local/lib/python3.12/site-packages/urllib3/util/connection.py", line 85, in create_connection
    raise err
  File "/home/airflow/.local/lib/python3.12/site-packages/urllib3/util/connection.py", line 73, in create_connection
    sock.connect(sa)
OSError: [Errno 101] Network is unreachable

The above exception was the direct cause of the following exception:

Traceback (most recent call last):
  File "/home/airflow/.local/lib/python3.12/site-packages/urllib3/connectionpool.py", line 789, in urlopen
    response = self._make_request(
               ^^^^^^^^^^^^^^^^^^^
  File "/home/airflow/.local/lib/python3.12/site-packages/urllib3/connectionpool.py", line 490, in _make_request
    raise new_e
  File "/home/airflow/.local/lib/python3.12/site-packages/urllib3/connectionpool.py", line 466, in _make_request
    self._validate_conn(conn)
  File "/home/airflow/.local/lib/python3.12/site-packages/urllib3/connectionpool.py", line 1095, in _validate_conn
    conn.connect()
  File "/home/airflow/.local/lib/python3.12/site-packages/urllib3/connection.py", line 615, in connect
    self.sock = sock = self._new_conn()
                       ^^^^^^^^^^^^^^^^
  File "/home/airflow/.local/lib/python3.12/site-packages/urllib3/connection.py", line 211, in _new_conn
    raise NewConnectionError(
urllib3.exceptions.NewConnectionError: <urllib3.connection.HTTPSConnection object at 0x7cb79c173590>: Failed to establish a new connection: [Errno 101] Network is unreachable

The above exception was the direct cause of the following exception:

Traceback (most recent call last):
  File "/home/airflow/.local/lib/python3.12/site-packages/requests/adapters.py", line 667, in send
    resp = conn.urlopen(
           ^^^^^^^^^^^^^
  File "/home/airflow/.local/lib/python3.12/site-packages/urllib3/connectionpool.py", line 843, in urlopen
    retries = retries.increment(
              ^^^^^^^^^^^^^^^^^^
  File "/home/airflow/.local/lib/python3.12/site-packages/urllib3/util/retry.py", line 519, in increment
    raise MaxRetryError(_pool, url, reason) from reason  # type: ignore[arg-type]
    ^^^^^^^^^^^^^^^^^^^^^^^^^^^^^^^^^^^^^^^^^^^^^^^^^^^
urllib3.exceptions.MaxRetryError: HTTPSConnectionPool(host='api.inaturalist.org', port=443): Max retries exceeded with url: /v1/observations?geo=true&iconic_taxa=Amphibia%2CAves%2CMammalia%2CReptilia%2Cunknown&id_above=18733787&q=atropelada&page=1&per_page=5&order=asc&order_by=id (Caused by NewConnectionError('<urllib3.connection.HTTPSConnection object at 0x7cb79c173590>: Failed to establish a new connection: [Errno 101] Network is unreachable'))

During handling of the above exception, another exception occurred:

Traceback (most recent call last):
  File "/home/airflow/.local/lib/python3.12/site-packages/airflow/task/task_runner/standard_task_runner.py", line 117, in _start_by_fork
    ret = args.func(args, dag=self.dag)
          ^^^^^^^^^^^^^^^^^^^^^^^^^^^^^
  File "/home/airflow/.local/lib/python3.12/site-packages/airflow/cli/cli_config.py", line 49, in command
    return func(*args, **kwargs)
           ^^^^^^^^^^^^^^^^^^^^^
  File "/home/airflow/.local/lib/python3.12/site-packages/airflow/utils/cli.py", line 115, in wrapper
    return f(*args, **kwargs)
           ^^^^^^^^^^^^^^^^^^
  File "/home/airflow/.local/lib/python3.12/site-packages/airflow/cli/commands/task_command.py", line 483, in task_run
    task_return_code = _run_task_by_selected_method(args, _dag, ti)
                       ^^^^^^^^^^^^^^^^^^^^^^^^^^^^^^^^^^^^^^^^^^^^
  File "/home/airflow/.local/lib/python3.12/site-packages/airflow/cli/commands/task_command.py", line 256, in _run_task_by_selected_method
    return _run_raw_task(args, ti)
           ^^^^^^^^^^^^^^^^^^^^^^^
  File "/home/airflow/.local/lib/python3.12/site-packages/airflow/cli/commands/task_command.py", line 341, in _run_raw_task
    return ti._run_raw_task(
           ^^^^^^^^^^^^^^^^^
  File "/home/airflow/.local/lib/python3.12/site-packages/airflow/utils/session.py", line 97, in wrapper
    return func(*args, session=session, **kwargs)
           ^^^^^^^^^^^^^^^^^^^^^^^^^^^^^^^^^^^^^^
  File "/home/airflow/.local/lib/python3.12/site-packages/airflow/models/taskinstance.py", line 3004, in _run_raw_task
    return _run_raw_task(
           ^^^^^^^^^^^^^^
  File "/home/airflow/.local/lib/python3.12/site-packages/airflow/models/taskinstance.py", line 273, in _run_raw_task
    TaskInstance._execute_task_with_callbacks(
  File "/home/airflow/.local/lib/python3.12/site-packages/airflow/models/taskinstance.py", line 3158, in _execute_task_with_callbacks
    result = self._execute_task(context, task_orig)
             ^^^^^^^^^^^^^^^^^^^^^^^^^^^^^^^^^^^^^^
  File "/home/airflow/.local/lib/python3.12/site-packages/airflow/models/taskinstance.py", line 3182, in _execute_task
    return _execute_task(self, context, task_orig)
           ^^^^^^^^^^^^^^^^^^^^^^^^^^^^^^^^^^^^^^^
  File "/home/airflow/.local/lib/python3.12/site-packages/airflow/models/taskinstance.py", line 767, in _execute_task
    result = _execute_callable(context=context, **execute_callable_kwargs)
             ^^^^^^^^^^^^^^^^^^^^^^^^^^^^^^^^^^^^^^^^^^^^^^^^^^^^^^^^^^^^^
  File "/home/airflow/.local/lib/python3.12/site-packages/airflow/models/taskinstance.py", line 733, in _execute_callable
    return ExecutionCallableRunner(
           ^^^^^^^^^^^^^^^^^^^^^^^^
  File "/home/airflow/.local/lib/python3.12/site-packages/airflow/utils/operator_helpers.py", line 252, in run
    return self.func(*args, **kwargs)
           ^^^^^^^^^^^^^^^^^^^^^^^^^^
  File "/home/airflow/.local/lib/python3.12/site-packages/airflow/models/baseoperator.py", line 406, in wrapper
    return func(self, *args, **kwargs)
           ^^^^^^^^^^^^^^^^^^^^^^^^^^^
  File "/home/airflow/.local/lib/python3.12/site-packages/airflow/decorators/base.py", line 266, in execute
    return_value = super().execute(context)
                   ^^^^^^^^^^^^^^^^^^^^^^^^
  File "/home/airflow/.local/lib/python3.12/site-packages/airflow/models/baseoperator.py", line 406, in wrapper
    return func(self, *args, **kwargs)
           ^^^^^^^^^^^^^^^^^^^^^^^^^^^
  File "/home/airflow/.local/lib/python3.12/site-packages/airflow/operators/python.py", line 238, in execute
    return_value = self.execute_callable()
                   ^^^^^^^^^^^^^^^^^^^^^^^
  File "/home/airflow/.local/lib/python3.12/site-packages/airflow/operators/python.py", line 256, in execute_callable
    return runner.run(*self.op_args, **self.op_kwargs)
           ^^^^^^^^^^^^^^^^^^^^^^^^^^^^^^^^^^^^^^^^^^^
  File "/home/airflow/.local/lib/python3.12/site-packages/airflow/utils/operator_helpers.py", line 252, in run
    return self.func(*args, **kwargs)
           ^^^^^^^^^^^^^^^^^^^^^^^^^^
  File "/opt/airflow/dags/inaturalist_dag.py", line 132, in get_all_data
    last_observation_id, observations_extracted = get_data(maximum_id)
                                                  ^^^^^^^^^^^^^^^^^^^^
  File "/opt/airflow/dags/inaturalist_dag.py", line 61, in get_data
    response = requests.get(API_URL, params=params)
               ^^^^^^^^^^^^^^^^^^^^^^^^^^^^^^^^^^^^
  File "/home/airflow/.local/lib/python3.12/site-packages/requests/api.py", line 73, in get
    return request("get", url, params=params, **kwargs)
           ^^^^^^^^^^^^^^^^^^^^^^^^^^^^^^^^^^^^^^^^^^^^
  File "/home/airflow/.local/lib/python3.12/site-packages/requests/api.py", line 59, in request
    return session.request(method=method, url=url, **kwargs)
           ^^^^^^^^^^^^^^^^^^^^^^^^^^^^^^^^^^^^^^^^^^^^^^^^^
  File "/home/airflow/.local/lib/python3.12/site-packages/requests/sessions.py", line 589, in request
    resp = self.send(prep, **send_kwargs)
           ^^^^^^^^^^^^^^^^^^^^^^^^^^^^^^
  File "/home/airflow/.local/lib/python3.12/site-packages/requests/sessions.py", line 703, in send
    r = adapter.send(request, **kwargs)
        ^^^^^^^^^^^^^^^^^^^^^^^^^^^^^^^
  File "/home/airflow/.local/lib/python3.12/site-packages/requests/adapters.py", line 700, in send
    raise ConnectionError(e, request=request)
requests.exceptions.ConnectionError: HTTPSConnectionPool(host='api.inaturalist.org', port=443): Max retries exceeded with url: /v1/observations?geo=true&iconic_taxa=Amphibia%2CAves%2CMammalia%2CReptilia%2Cunknown&id_above=18733787&q=atropelada&page=1&per_page=5&order=asc&order_by=id (Caused by NewConnectionError('<urllib3.connection.HTTPSConnection object at 0x7cb79c173590>: Failed to establish a new connection: [Errno 101] Network is unreachable'))
[2024-11-19T10:56:40.979+0000] {local_task_job_runner.py:266} INFO - Task exited with return code 1
[2024-11-19T10:56:40.992+0000] {local_task_job_runner.py:245} INFO - ::endgroup::
