[2024-12-18T23:27:06.382+0000] {local_task_job_runner.py:123} INFO - ::group::Pre task execution logs
[2024-12-18T23:27:06.398+0000] {taskinstance.py:2612} INFO - Dependencies all met for dep_context=non-requeueable deps ti=<TaskInstance: get_inaturalist_data_roadkill.save_data scheduled__2024-12-18T16:00:00+00:00 [queued]>
[2024-12-18T23:27:06.407+0000] {taskinstance.py:2612} INFO - Dependencies all met for dep_context=requeueable deps ti=<TaskInstance: get_inaturalist_data_roadkill.save_data scheduled__2024-12-18T16:00:00+00:00 [queued]>
[2024-12-18T23:27:06.407+0000] {taskinstance.py:2865} INFO - Starting attempt 3 of 4
[2024-12-18T23:27:06.418+0000] {taskinstance.py:2888} INFO - Executing <Task(_PythonDecoratedOperator): save_data> on 2024-12-18 16:00:00+00:00
[2024-12-18T23:27:06.425+0000] {warnings.py:112} WARNING - /home/***/.local/lib/python3.12/site-packages/***/task/task_runner/standard_task_runner.py:70: DeprecationWarning: This process (pid=139) is multi-threaded, use of fork() may lead to deadlocks in the child.
  pid = os.fork()

[2024-12-18T23:27:06.426+0000] {standard_task_runner.py:72} INFO - Started process 148 to run task
[2024-12-18T23:27:06.427+0000] {standard_task_runner.py:104} INFO - Running: ['***', 'tasks', 'run', 'get_inaturalist_data_roadkill', 'save_data', 'scheduled__2024-12-18T16:00:00+00:00', '--job-id', '255', '--raw', '--subdir', 'DAGS_FOLDER/inaturalist_dag.py', '--cfg-path', '/tmp/tmp_aoe2sf8']
[2024-12-18T23:27:06.428+0000] {standard_task_runner.py:105} INFO - Job 255: Subtask save_data
[2024-12-18T23:27:06.464+0000] {task_command.py:467} INFO - Running <TaskInstance: get_inaturalist_data_roadkill.save_data scheduled__2024-12-18T16:00:00+00:00 [running]> on host e919aa2070f5
[2024-12-18T23:27:06.567+0000] {taskinstance.py:3131} INFO - Exporting env vars: AIRFLOW_CTX_DAG_OWNER='***' AIRFLOW_CTX_DAG_ID='get_inaturalist_data_roadkill' AIRFLOW_CTX_TASK_ID='save_data' AIRFLOW_CTX_EXECUTION_DATE='2024-12-18T16:00:00+00:00' AIRFLOW_CTX_TRY_NUMBER='3' AIRFLOW_CTX_DAG_RUN_ID='scheduled__2024-12-18T16:00:00+00:00'
[2024-12-18T23:27:06.568+0000] {taskinstance.py:731} INFO - ::endgroup::
[2024-12-18T23:27:06.592+0000] {connectionpool.py:870} WARNING - Retrying (Retry(total=4, connect=None, read=None, redirect=None, status=None)) after connection broken by 'NameResolutionError("<urllib3.connection.HTTPConnection object at 0x7320a263d1c0>: Failed to resolve 'minio' ([Errno -2] Name or service not known)")': /environbit?location=
[2024-12-18T23:27:06.998+0000] {connectionpool.py:870} WARNING - Retrying (Retry(total=3, connect=None, read=None, redirect=None, status=None)) after connection broken by 'NameResolutionError("<urllib3.connection.HTTPConnection object at 0x7320a263d520>: Failed to resolve 'minio' ([Errno -2] Name or service not known)")': /environbit?location=
[2024-12-18T23:27:07.806+0000] {connectionpool.py:870} WARNING - Retrying (Retry(total=2, connect=None, read=None, redirect=None, status=None)) after connection broken by 'NameResolutionError("<urllib3.connection.HTTPConnection object at 0x7320a263d790>: Failed to resolve 'minio' ([Errno -2] Name or service not known)")': /environbit?location=
[2024-12-18T23:27:09.411+0000] {connectionpool.py:870} WARNING - Retrying (Retry(total=1, connect=None, read=None, redirect=None, status=None)) after connection broken by 'NameResolutionError("<urllib3.connection.HTTPConnection object at 0x7320a263dbb0>: Failed to resolve 'minio' ([Errno -2] Name or service not known)")': /environbit?location=
[2024-12-18T23:27:12.616+0000] {connectionpool.py:870} WARNING - Retrying (Retry(total=0, connect=None, read=None, redirect=None, status=None)) after connection broken by 'NameResolutionError("<urllib3.connection.HTTPConnection object at 0x7320a263deb0>: Failed to resolve 'minio' ([Errno -2] Name or service not known)")': /environbit?location=
[2024-12-18T23:27:12.622+0000] {taskinstance.py:3310} ERROR - Task failed with exception
Traceback (most recent call last):
  File "/home/airflow/.local/lib/python3.12/site-packages/urllib3/connection.py", line 196, in _new_conn
    sock = connection.create_connection(
           ^^^^^^^^^^^^^^^^^^^^^^^^^^^^^
  File "/home/airflow/.local/lib/python3.12/site-packages/urllib3/util/connection.py", line 60, in create_connection
    for res in socket.getaddrinfo(host, port, family, socket.SOCK_STREAM):
               ^^^^^^^^^^^^^^^^^^^^^^^^^^^^^^^^^^^^^^^^^^^^^^^^^^^^^^^^^^
  File "/usr/local/lib/python3.12/socket.py", line 976, in getaddrinfo
    for res in _socket.getaddrinfo(host, port, family, type, proto, flags):
               ^^^^^^^^^^^^^^^^^^^^^^^^^^^^^^^^^^^^^^^^^^^^^^^^^^^^^^^^^^^
socket.gaierror: [Errno -2] Name or service not known

The above exception was the direct cause of the following exception:

Traceback (most recent call last):
  File "/home/airflow/.local/lib/python3.12/site-packages/urllib3/connectionpool.py", line 789, in urlopen
    response = self._make_request(
               ^^^^^^^^^^^^^^^^^^^
  File "/home/airflow/.local/lib/python3.12/site-packages/urllib3/connectionpool.py", line 495, in _make_request
    conn.request(
  File "/home/airflow/.local/lib/python3.12/site-packages/urllib3/connection.py", line 398, in request
    self.endheaders()
  File "/usr/local/lib/python3.12/http/client.py", line 1331, in endheaders
    self._send_output(message_body, encode_chunked=encode_chunked)
  File "/usr/local/lib/python3.12/http/client.py", line 1091, in _send_output
    self.send(msg)
  File "/usr/local/lib/python3.12/http/client.py", line 1035, in send
    self.connect()
  File "/home/airflow/.local/lib/python3.12/site-packages/urllib3/connection.py", line 236, in connect
    self.sock = self._new_conn()
                ^^^^^^^^^^^^^^^^
  File "/home/airflow/.local/lib/python3.12/site-packages/urllib3/connection.py", line 203, in _new_conn
    raise NameResolutionError(self.host, self, e) from e
urllib3.exceptions.NameResolutionError: <urllib3.connection.HTTPConnection object at 0x7320a263e3c0>: Failed to resolve 'minio' ([Errno -2] Name or service not known)

The above exception was the direct cause of the following exception:

Traceback (most recent call last):
  File "/home/airflow/.local/lib/python3.12/site-packages/airflow/models/taskinstance.py", line 767, in _execute_task
    result = _execute_callable(context=context, **execute_callable_kwargs)
             ^^^^^^^^^^^^^^^^^^^^^^^^^^^^^^^^^^^^^^^^^^^^^^^^^^^^^^^^^^^^^
  File "/home/airflow/.local/lib/python3.12/site-packages/airflow/models/taskinstance.py", line 733, in _execute_callable
    return ExecutionCallableRunner(
           ^^^^^^^^^^^^^^^^^^^^^^^^
  File "/home/airflow/.local/lib/python3.12/site-packages/airflow/utils/operator_helpers.py", line 252, in run
    return self.func(*args, **kwargs)
           ^^^^^^^^^^^^^^^^^^^^^^^^^^
  File "/home/airflow/.local/lib/python3.12/site-packages/airflow/models/baseoperator.py", line 406, in wrapper
    return func(self, *args, **kwargs)
           ^^^^^^^^^^^^^^^^^^^^^^^^^^^
  File "/home/airflow/.local/lib/python3.12/site-packages/airflow/decorators/base.py", line 266, in execute
    return_value = super().execute(context)
                   ^^^^^^^^^^^^^^^^^^^^^^^^
  File "/home/airflow/.local/lib/python3.12/site-packages/airflow/models/baseoperator.py", line 406, in wrapper
    return func(self, *args, **kwargs)
           ^^^^^^^^^^^^^^^^^^^^^^^^^^^
  File "/home/airflow/.local/lib/python3.12/site-packages/airflow/operators/python.py", line 238, in execute
    return_value = self.execute_callable()
                   ^^^^^^^^^^^^^^^^^^^^^^^
  File "/home/airflow/.local/lib/python3.12/site-packages/airflow/operators/python.py", line 256, in execute_callable
    return runner.run(*self.op_args, **self.op_kwargs)
           ^^^^^^^^^^^^^^^^^^^^^^^^^^^^^^^^^^^^^^^^^^^
  File "/home/airflow/.local/lib/python3.12/site-packages/airflow/utils/operator_helpers.py", line 252, in run
    return self.func(*args, **kwargs)
           ^^^^^^^^^^^^^^^^^^^^^^^^^^
  File "/opt/airflow/dags/inaturalist_dag.py", line 219, in save_data
    connector.upload_data(data=csv_buffer,
  File "/opt/airflow/connectors/minio.py", line 29, in upload_data
    if not self.client.bucket_exists(self.bucket_name):
           ^^^^^^^^^^^^^^^^^^^^^^^^^^^^^^^^^^^^^^^^^^^
  File "/home/airflow/.local/lib/python3.12/site-packages/minio/api.py", line 696, in bucket_exists
    self._execute("HEAD", bucket_name)
  File "/home/airflow/.local/lib/python3.12/site-packages/minio/api.py", line 437, in _execute
    region = self._get_region(bucket_name)
             ^^^^^^^^^^^^^^^^^^^^^^^^^^^^^
  File "/home/airflow/.local/lib/python3.12/site-packages/minio/api.py", line 494, in _get_region
    response = self._url_open(
               ^^^^^^^^^^^^^^^
  File "/home/airflow/.local/lib/python3.12/site-packages/minio/api.py", line 302, in _url_open
    response = self._http.urlopen(
               ^^^^^^^^^^^^^^^^^^^
  File "/home/airflow/.local/lib/python3.12/site-packages/urllib3/poolmanager.py", line 443, in urlopen
    response = conn.urlopen(method, u.request_uri, **kw)
               ^^^^^^^^^^^^^^^^^^^^^^^^^^^^^^^^^^^^^^^^^
  File "/home/airflow/.local/lib/python3.12/site-packages/urllib3/connectionpool.py", line 873, in urlopen
    return self.urlopen(
           ^^^^^^^^^^^^^
  File "/home/airflow/.local/lib/python3.12/site-packages/urllib3/connectionpool.py", line 873, in urlopen
    return self.urlopen(
           ^^^^^^^^^^^^^
  File "/home/airflow/.local/lib/python3.12/site-packages/urllib3/connectionpool.py", line 873, in urlopen
    return self.urlopen(
           ^^^^^^^^^^^^^
  [Previous line repeated 2 more times]
  File "/home/airflow/.local/lib/python3.12/site-packages/urllib3/connectionpool.py", line 843, in urlopen
    retries = retries.increment(
              ^^^^^^^^^^^^^^^^^^
  File "/home/airflow/.local/lib/python3.12/site-packages/urllib3/util/retry.py", line 519, in increment
    raise MaxRetryError(_pool, url, reason) from reason  # type: ignore[arg-type]
    ^^^^^^^^^^^^^^^^^^^^^^^^^^^^^^^^^^^^^^^^^^^^^^^^^^^
urllib3.exceptions.MaxRetryError: HTTPConnectionPool(host='minio', port=9000): Max retries exceeded with url: /environbit?location= (Caused by NameResolutionError("<urllib3.connection.HTTPConnection object at 0x7320a263e3c0>: Failed to resolve 'minio' ([Errno -2] Name or service not known)"))
[2024-12-18T23:27:12.641+0000] {taskinstance.py:1225} INFO - Marking task as UP_FOR_RETRY. dag_id=get_inaturalist_data_roadkill, task_id=save_data, run_id=scheduled__2024-12-18T16:00:00+00:00, execution_date=20241218T160000, start_date=20241218T232706, end_date=20241218T232712
[2024-12-18T23:27:12.659+0000] {taskinstance.py:340} INFO - ::group::Post task execution logs
[2024-12-18T23:27:12.660+0000] {standard_task_runner.py:124} ERROR - Failed to execute job 255 for task save_data (HTTPConnectionPool(host='minio', port=9000): Max retries exceeded with url: /environbit?location= (Caused by NameResolutionError("<urllib3.connection.HTTPConnection object at 0x7320a263e3c0>: Failed to resolve 'minio' ([Errno -2] Name or service not known)")); 148)
Traceback (most recent call last):
  File "/home/airflow/.local/lib/python3.12/site-packages/urllib3/connection.py", line 196, in _new_conn
    sock = connection.create_connection(
           ^^^^^^^^^^^^^^^^^^^^^^^^^^^^^
  File "/home/airflow/.local/lib/python3.12/site-packages/urllib3/util/connection.py", line 60, in create_connection
    for res in socket.getaddrinfo(host, port, family, socket.SOCK_STREAM):
               ^^^^^^^^^^^^^^^^^^^^^^^^^^^^^^^^^^^^^^^^^^^^^^^^^^^^^^^^^^
  File "/usr/local/lib/python3.12/socket.py", line 976, in getaddrinfo
    for res in _socket.getaddrinfo(host, port, family, type, proto, flags):
               ^^^^^^^^^^^^^^^^^^^^^^^^^^^^^^^^^^^^^^^^^^^^^^^^^^^^^^^^^^^
socket.gaierror: [Errno -2] Name or service not known

The above exception was the direct cause of the following exception:

Traceback (most recent call last):
  File "/home/airflow/.local/lib/python3.12/site-packages/urllib3/connectionpool.py", line 789, in urlopen
    response = self._make_request(
               ^^^^^^^^^^^^^^^^^^^
  File "/home/airflow/.local/lib/python3.12/site-packages/urllib3/connectionpool.py", line 495, in _make_request
    conn.request(
  File "/home/airflow/.local/lib/python3.12/site-packages/urllib3/connection.py", line 398, in request
    self.endheaders()
  File "/usr/local/lib/python3.12/http/client.py", line 1331, in endheaders
    self._send_output(message_body, encode_chunked=encode_chunked)
  File "/usr/local/lib/python3.12/http/client.py", line 1091, in _send_output
    self.send(msg)
  File "/usr/local/lib/python3.12/http/client.py", line 1035, in send
    self.connect()
  File "/home/airflow/.local/lib/python3.12/site-packages/urllib3/connection.py", line 236, in connect
    self.sock = self._new_conn()
                ^^^^^^^^^^^^^^^^
  File "/home/airflow/.local/lib/python3.12/site-packages/urllib3/connection.py", line 203, in _new_conn
    raise NameResolutionError(self.host, self, e) from e
urllib3.exceptions.NameResolutionError: <urllib3.connection.HTTPConnection object at 0x7320a263e3c0>: Failed to resolve 'minio' ([Errno -2] Name or service not known)

The above exception was the direct cause of the following exception:

Traceback (most recent call last):
  File "/home/airflow/.local/lib/python3.12/site-packages/airflow/task/task_runner/standard_task_runner.py", line 117, in _start_by_fork
    ret = args.func(args, dag=self.dag)
          ^^^^^^^^^^^^^^^^^^^^^^^^^^^^^
  File "/home/airflow/.local/lib/python3.12/site-packages/airflow/cli/cli_config.py", line 49, in command
    return func(*args, **kwargs)
           ^^^^^^^^^^^^^^^^^^^^^
  File "/home/airflow/.local/lib/python3.12/site-packages/airflow/utils/cli.py", line 115, in wrapper
    return f(*args, **kwargs)
           ^^^^^^^^^^^^^^^^^^
  File "/home/airflow/.local/lib/python3.12/site-packages/airflow/cli/commands/task_command.py", line 483, in task_run
    task_return_code = _run_task_by_selected_method(args, _dag, ti)
                       ^^^^^^^^^^^^^^^^^^^^^^^^^^^^^^^^^^^^^^^^^^^^
  File "/home/airflow/.local/lib/python3.12/site-packages/airflow/cli/commands/task_command.py", line 256, in _run_task_by_selected_method
    return _run_raw_task(args, ti)
           ^^^^^^^^^^^^^^^^^^^^^^^
  File "/home/airflow/.local/lib/python3.12/site-packages/airflow/cli/commands/task_command.py", line 341, in _run_raw_task
    return ti._run_raw_task(
           ^^^^^^^^^^^^^^^^^
  File "/home/airflow/.local/lib/python3.12/site-packages/airflow/utils/session.py", line 97, in wrapper
    return func(*args, session=session, **kwargs)
           ^^^^^^^^^^^^^^^^^^^^^^^^^^^^^^^^^^^^^^
  File "/home/airflow/.local/lib/python3.12/site-packages/airflow/models/taskinstance.py", line 3004, in _run_raw_task
    return _run_raw_task(
           ^^^^^^^^^^^^^^
  File "/home/airflow/.local/lib/python3.12/site-packages/airflow/models/taskinstance.py", line 273, in _run_raw_task
    TaskInstance._execute_task_with_callbacks(
  File "/home/airflow/.local/lib/python3.12/site-packages/airflow/models/taskinstance.py", line 3158, in _execute_task_with_callbacks
    result = self._execute_task(context, task_orig)
             ^^^^^^^^^^^^^^^^^^^^^^^^^^^^^^^^^^^^^^
  File "/home/airflow/.local/lib/python3.12/site-packages/airflow/models/taskinstance.py", line 3182, in _execute_task
    return _execute_task(self, context, task_orig)
           ^^^^^^^^^^^^^^^^^^^^^^^^^^^^^^^^^^^^^^^
  File "/home/airflow/.local/lib/python3.12/site-packages/airflow/models/taskinstance.py", line 767, in _execute_task
    result = _execute_callable(context=context, **execute_callable_kwargs)
             ^^^^^^^^^^^^^^^^^^^^^^^^^^^^^^^^^^^^^^^^^^^^^^^^^^^^^^^^^^^^^
  File "/home/airflow/.local/lib/python3.12/site-packages/airflow/models/taskinstance.py", line 733, in _execute_callable
    return ExecutionCallableRunner(
           ^^^^^^^^^^^^^^^^^^^^^^^^
  File "/home/airflow/.local/lib/python3.12/site-packages/airflow/utils/operator_helpers.py", line 252, in run
    return self.func(*args, **kwargs)
           ^^^^^^^^^^^^^^^^^^^^^^^^^^
  File "/home/airflow/.local/lib/python3.12/site-packages/airflow/models/baseoperator.py", line 406, in wrapper
    return func(self, *args, **kwargs)
           ^^^^^^^^^^^^^^^^^^^^^^^^^^^
  File "/home/airflow/.local/lib/python3.12/site-packages/airflow/decorators/base.py", line 266, in execute
    return_value = super().execute(context)
                   ^^^^^^^^^^^^^^^^^^^^^^^^
  File "/home/airflow/.local/lib/python3.12/site-packages/airflow/models/baseoperator.py", line 406, in wrapper
    return func(self, *args, **kwargs)
           ^^^^^^^^^^^^^^^^^^^^^^^^^^^
  File "/home/airflow/.local/lib/python3.12/site-packages/airflow/operators/python.py", line 238, in execute
    return_value = self.execute_callable()
                   ^^^^^^^^^^^^^^^^^^^^^^^
  File "/home/airflow/.local/lib/python3.12/site-packages/airflow/operators/python.py", line 256, in execute_callable
    return runner.run(*self.op_args, **self.op_kwargs)
           ^^^^^^^^^^^^^^^^^^^^^^^^^^^^^^^^^^^^^^^^^^^
  File "/home/airflow/.local/lib/python3.12/site-packages/airflow/utils/operator_helpers.py", line 252, in run
    return self.func(*args, **kwargs)
           ^^^^^^^^^^^^^^^^^^^^^^^^^^
  File "/opt/airflow/dags/inaturalist_dag.py", line 219, in save_data
    connector.upload_data(data=csv_buffer,
  File "/opt/airflow/connectors/minio.py", line 29, in upload_data
    if not self.client.bucket_exists(self.bucket_name):
           ^^^^^^^^^^^^^^^^^^^^^^^^^^^^^^^^^^^^^^^^^^^
  File "/home/airflow/.local/lib/python3.12/site-packages/minio/api.py", line 696, in bucket_exists
    self._execute("HEAD", bucket_name)
  File "/home/airflow/.local/lib/python3.12/site-packages/minio/api.py", line 437, in _execute
    region = self._get_region(bucket_name)
             ^^^^^^^^^^^^^^^^^^^^^^^^^^^^^
  File "/home/airflow/.local/lib/python3.12/site-packages/minio/api.py", line 494, in _get_region
    response = self._url_open(
               ^^^^^^^^^^^^^^^
  File "/home/airflow/.local/lib/python3.12/site-packages/minio/api.py", line 302, in _url_open
    response = self._http.urlopen(
               ^^^^^^^^^^^^^^^^^^^
  File "/home/airflow/.local/lib/python3.12/site-packages/urllib3/poolmanager.py", line 443, in urlopen
    response = conn.urlopen(method, u.request_uri, **kw)
               ^^^^^^^^^^^^^^^^^^^^^^^^^^^^^^^^^^^^^^^^^
  File "/home/airflow/.local/lib/python3.12/site-packages/urllib3/connectionpool.py", line 873, in urlopen
    return self.urlopen(
           ^^^^^^^^^^^^^
  File "/home/airflow/.local/lib/python3.12/site-packages/urllib3/connectionpool.py", line 873, in urlopen
    return self.urlopen(
           ^^^^^^^^^^^^^
  File "/home/airflow/.local/lib/python3.12/site-packages/urllib3/connectionpool.py", line 873, in urlopen
    return self.urlopen(
           ^^^^^^^^^^^^^
  [Previous line repeated 2 more times]
  File "/home/airflow/.local/lib/python3.12/site-packages/urllib3/connectionpool.py", line 843, in urlopen
    retries = retries.increment(
              ^^^^^^^^^^^^^^^^^^
  File "/home/airflow/.local/lib/python3.12/site-packages/urllib3/util/retry.py", line 519, in increment
    raise MaxRetryError(_pool, url, reason) from reason  # type: ignore[arg-type]
    ^^^^^^^^^^^^^^^^^^^^^^^^^^^^^^^^^^^^^^^^^^^^^^^^^^^
urllib3.exceptions.MaxRetryError: HTTPConnectionPool(host='minio', port=9000): Max retries exceeded with url: /environbit?location= (Caused by NameResolutionError("<urllib3.connection.HTTPConnection object at 0x7320a263e3c0>: Failed to resolve 'minio' ([Errno -2] Name or service not known)"))
[2024-12-18T23:27:12.687+0000] {local_task_job_runner.py:266} INFO - Task exited with return code 1
[2024-12-18T23:27:12.706+0000] {taskinstance.py:3900} INFO - 0 downstream tasks scheduled from follow-on schedule check
[2024-12-18T23:27:12.707+0000] {local_task_job_runner.py:245} INFO - ::endgroup::
